Workbook
Name UPDATE: 'Data Sheet'!$E$1

Sheet About 

Sheet Financials>

Sheet Historical FS
B2: ="Historical Financial Statements - "&'Data Sheet'!B1 -> Historical Financial Statements - INDIAN RAILWAY FINANCE CORPORATION LTD
B3: Year | C3: ='Data Sheet'!B16 -> 42094 | D3: ='Data Sheet'!C16 -> 42460 | E3: ='Data Sheet'!D16 -> 42825 | F3: ='Data Sheet'!E16 -> 43190 | G3: ='Data Sheet'!F16 -> 43555 | H3: ='Data Sheet'!G16 -> 43921 | I3: ='Data Sheet'!H16 -> 44286 | J3: ='Data Sheet'!I16 -> 44651 | ... L3: ='Data Sheet'!K16 -> 45382 | M3: LTM
A5: # | B5: Income statement
B7: Sales | C7: =IFERROR('Data Sheet'!B17,0) -> 6939.19 | D7: =IFERROR('Data Sheet'!C17,0) -> 7506.69 | E7: =IFERROR('Data Sheet'!D17,0) -> 9047.38 | F7: =IFERROR('Data Sheet'!E17,0) -> 9267.14 | G7: =IFERROR('Data Sheet'!F17,0) -> 11133.59 | H7: =IFERROR('Data Sheet'!G17,0) -> 13421.02 | I7: =IFERROR('Data Sheet'!H17,0) -> 15770.51 | J7: =IFERROR('Data Sheet'!I17,0) -> 20299.38 | ... L7: =IFERROR('Data Sheet'!K17,0) -> 26645.47 | M7: =IFERROR(SUM('Data Sheet'!H42:K42),0) -> 26742.42
B8: Sales Growth % | C8: 0 | D8: =D7/C7-1 -> 0.081781879 | E8: =E7/D7-1 -> 0.20524226 | F8: =F7/E7-1 -> 0.024289905 | G8: =G7/F7-1 -> 0.20140518 | H8: =H7/G7-1 -> 0.20545305 | I8: =I7/H7-1 -> 0.17506046 | J8: =J7/I7-1 -> 0.28717334 | K8: =K7/J7-1 -> 0.16861155 | ... M8: =M7/L7-1 -> 0.0036385172
B10: COGS | C10: =IFERROR(SUM('Data Sheet'!B18,'Data Sheet'!B20:B22)*1-'Data Sheet'!B19,0) -> 3.31 | D10: =IFERROR(SUM('Data Sheet'!C18,'Data Sheet'!C20:C22)*1-'Data Sheet'!C19,0) -> 4.29 | E10: =IFERROR(SUM('Data Sheet'!D18,'Data Sheet'!D20:D22)*1-'Data Sheet'!D19,0) -> 3.22 | F10: =IFERROR(SUM('Data Sheet'!E18,'Data Sheet'!E20:E22)*1-'Data Sheet'!E19,0) -> 5.77 | G10: =IFERROR(SUM('Data Sheet'!F18,'Data Sheet'!F20:F22)*1-'Data Sheet'!F19,0) -> 6.69 | H10: =IFERROR(SUM('Data Sheet'!G18,'Data Sheet'!G20:G22)*1-'Data Sheet'!G19,0) -> 8.84 | I10: =IFERROR(SUM('Data Sheet'!H18,'Data Sheet'!H20:H22)*1-'Data Sheet'!H19,0) -> 10.87 | J10: =IFERROR(SUM('Data Sheet'!I18,'Data Sheet'!I20:I22)*1-'Data Sheet'!I19,0) -> 15.28 | ... L10: =IFERROR(SUM('Data Sheet'!K18,'Data Sheet'!K20:K22)*1-'Data Sheet'!K19,0) -> 15.56 | M10: =IFERROR(SUM('Data Sheet'!H43:K43),0) -> 136.35
B11: COGS % Sales | C11: =C10/C7 -> 0.00047700092 | D11: =D10/D7 -> 0.00057149023 | E11: =E10/E7 -> 0.00035590414 | F11: =F10/F7 -> 0.00062263007 | G11: =G10/G7 -> 0.00060088435 | H11: =H10/H7 -> 0.00065866827 | I11: =I10/I7 -> 0.00068926116 | J11: =J10/J7 -> 0.00075273235 | ... M11: =M10/M7 -> 0.005098641
B13: Gross Profit | C13: =C7-C10 -> 6935.88 | D13: =D7-D10 -> 7502.4 | E13: =E7-E10 -> 9044.16 | F13: =F7-F10 -> 9261.37 | G13: =G7-G10 -> 11126.9 | H13: =H7-H10 -> 13412.18 | I13: =I7-I10 -> 15759.64 | J13: =J7-J10 -> 20284.1 | ... M13: =M7-M10 -> 26606.07
B14: Gross Margins % | C14: =C13/C7 -> 0.999523 | D14: =D13/D7 -> 0.99942851 | E14: =E13/E7 -> 0.9996441 | F14: =F13/F7 -> 0.99937737 | G14: =G13/G7 -> 0.99939912 | H14: =H13/H7 -> 0.99934133 | I14: =I13/I7 -> 0.99931074 | J14: =J13/J7 -> 0.99924727 | ... M14: =M13/M7 -> 0.99490136
B16: Selling & General Expenses | C16: =IFERROR(SUM('Data Sheet'!B23:B24),0) -> 30.4 | D16: =IFERROR(SUM('Data Sheet'!C23:C24),0) -> 33.91 | E16: =IFERROR(SUM('Data Sheet'!D23:D24),0) -> 22.67 | F16: =IFERROR(SUM('Data Sheet'!E23:E24),0) -> 32.17 | G16: =IFERROR(SUM('Data Sheet'!F23:F24),0) -> 41.78 | H16: =IFERROR(SUM('Data Sheet'!G23:G24),0) -> 56.99 | I16: =IFERROR(SUM('Data Sheet'!H23:H24),0) -> 102.36 | J16: =IFERROR(SUM('Data Sheet'!I23:I24),0) -> 107.36 | ... L16: =IFERROR(SUM('Data Sheet'!K23:K24),0) -> 117.3
B17: S&G Expenses % Sales | C17: =C16/C7 -> 0.0043809148 | D17: =D16/D7 -> 0.0045173039 | E17: =E16/E7 -> 0.0025056978 | F17: =F16/F7 -> 0.0034714054 | G17: =G16/G7 -> 0.0037526081 | H17: =H16/H7 -> 0.004246324 | I17: =I16/I7 -> 0.0064905954 | J17: =J16/J7 -> 0.0052888315 | ... L17: =L16/L7 -> 0.0044022492
B19: Other Income | C19: =IFERROR('Data Sheet'!B25,0) -> 0.97 | D19: =IFERROR('Data Sheet'!C25,0) -> 0.61 | E19: =IFERROR('Data Sheet'!D25,0) -> 0.26 | F19: =IFERROR('Data Sheet'!E25,0) -> 1.23 | G19: =IFERROR('Data Sheet'!F25,0) -> -0.02 | H19: =IFERROR('Data Sheet'!G25,0) -> 0.06 | I19: =IFERROR('Data Sheet'!H25,0) -> 0.33 | J19: =IFERROR('Data Sheet'!I25,0) -> 2.22 | ... L19: =IFERROR('Data Sheet'!K25,0) -> 10.41 | M19: =IFERROR(SUM('Data Sheet'!H44:K44),0) -> 9.09
B20: other income % sales | C20: =C19/C7 -> 0.00013978577 | D20: =D19/D7 -> 8.1260849e-05 | E20: =E19/E7 -> 2.8737601e-05 | F20: =F19/F7 -> 0.00013272703 | G20: =G19/G7 -> -1.7963658e-06 | H20: =H19/H7 -> 4.4705991e-06 | I20: =I19/I7 -> 2.0925132e-05 | J20: =J19/J7 -> 0.00010936295 | ... M20: =M19/M7 -> 0.0003399094
B22: EBITDA | C22: =C13-C16 -> 6905.48 | D22: =D13-D16 -> 7468.49 | E22: =E13-E16 -> 9021.49 | F22: =F13-F16 -> 9229.2 | G22: =G13-G16 -> 11085.12 | H22: =H13-H16 -> 13355.19 | I22: =I13-I16 -> 15657.28 | J22: =J13-J16 -> 20176.74 | ... L22: =L13-L16 -> 26512.61 | M22: =M13-M16+M19 -> 26615.16
B23: EBITDA Margin % | C23: =C22/C7 -> 0.99514208 | D23: =D22/D7 -> 0.99491121 | E23: =E22/E7 -> 0.9971384 | F23: =F22/F7 -> 0.99590596 | G23: =G22/G7 -> 0.99564651 | H23: =H22/H7 -> 0.99509501 | I23: =I22/I7 -> 0.99282014 | J23: =J22/J7 -> 0.99395844 | ... M23: =M22/M7 -> 0.99524127
B25: Interest | C25: =IFERROR('Data Sheet'!B27,0) -> 4991.83 | D25: =IFERROR('Data Sheet'!C27,0) -> 5518.84 | E25: =IFERROR('Data Sheet'!D27,0) -> 6888.13 | F25: =IFERROR('Data Sheet'!E27,0) -> 6637.59 | G25: =IFERROR('Data Sheet'!F27,0) -> 8183.1 | H25: =IFERROR('Data Sheet'!G27,0) -> 10162.7 | I25: =IFERROR('Data Sheet'!H27,0) -> 11237.05 | J25: =IFERROR('Data Sheet'!I27,0) -> 14074.78 | ... L25: =IFERROR('Data Sheet'!K27,0) -> 20101.47 | M25: =IFERROR(SUM('Data Sheet'!H46:K46),0) -> 20165.41
B26: Interest % Sales | C26: =C25/C7 -> 0.71936782 | D26: =D25/D7 -> 0.73518954 | E26: =E25/E7 -> 0.76133975 | F26: =F25/F7 -> 0.71625011 | G26: =G25/G7 -> 0.73499204 | H26: =H25/H7 -> 0.75722263 | I26: =I25/I7 -> 0.71253561 | J26: =J25/J7 -> 0.69336009 | ... M26: =M25/M7 -> 0.75406078
B28: Depreciation | C28: =IFERROR('Data Sheet'!B26,0) -> 0.44 | D28: =IFERROR('Data Sheet'!C26,0) -> 0.35 | E28: =IFERROR('Data Sheet'!D26,0) -> 0.35 | F28: =IFERROR('Data Sheet'!E26,0) -> 0.35 | G28: =IFERROR('Data Sheet'!F26,0) -> 0.42 | H28: =IFERROR('Data Sheet'!G26,0) -> 0.46 | I28: =IFERROR('Data Sheet'!H26,0) -> 4.43 | J28: =IFERROR('Data Sheet'!I26,0) -> 14.03 | ... L28: =IFERROR('Data Sheet'!K26,0) -> 9.44 | M28: =IFERROR(SUM('Data Sheet'!H45:K45),0) -> 6.8
B29: Depreciation % Sales | C29: =C28/C7 -> 6.3407977e-05 | D29: =D28/D7 -> 4.6625077e-05 | E29: =E28/E7 -> 3.8685233e-05 | F29: =F28/F7 -> 3.7767855e-05 | G29: =G28/G7 -> 3.7723681e-05 | H29: =H28/H7 -> 3.4274593e-05 | I29: =I28/I7 -> 0.00028090404 | J29: =J28/J7 -> 0.00069115411 | ... M29: =M28/M7 -> 0.00025427766
B31: EBT | C31: =C22-SUM(C25,C28) -> 1913.21 | D31: =D22-SUM(D25,D28) -> 1949.3 | E31: =E22-SUM(E25,E28) -> 2133.01 | F31: =F22-SUM(F25,F28) -> 2591.26 | G31: =G22-SUM(G25,G28) -> 2901.6 | H31: =H22-SUM(H25,H28) -> 3192.03 | I31: =I22-SUM(I25,I28) -> 4415.8 | J31: =J22-SUM(J25,J28) -> 6087.93 | ... L31: =L22-SUM(L25,L28) -> 6401.7 | M31: =IFERROR(SUM('Data Sheet'!H47:K47),0) -> 6442.95
B32: EBT % Sales | C32: =C31/C7 -> 0.27571085 | D32: =D31/D7 -> 0.25967504 | E32: =E31/E7 -> 0.23575997 | F32: =F31/F7 -> 0.27961809 | G32: =G31/G7 -> 0.26061675 | H32: =H31/H7 -> 0.23783811 | I32: =I31/I7 -> 0.28000363 | J32: =J31/J7 -> 0.29990719 | ... M32: =M31/M7 -> 0.24092621
B34: Tax | C34: =IFERROR('Data Sheet'!B29,0) -> 1155.88 | D34: =IFERROR('Data Sheet'!C29,0) -> 1101.22 | E34: =IFERROR('Data Sheet'!D29,0) -> 1199.46 | F34: =IFERROR('Data Sheet'!E29,0) -> 537.83 | G34: =IFERROR('Data Sheet'!F29,0) -> 646.84 | H34: =IFERROR('Data Sheet'!G29,0) -> 0 | I34: =IFERROR('Data Sheet'!H29,0) -> 0 | J34: =IFERROR('Data Sheet'!I29,0) -> 0.32 | ... L34: =IFERROR('Data Sheet'!K29,0) -> 0 | M34: =IFERROR(SUM('Data Sheet'!H48:K48),0) -> 0
B35: Effective Tax Rate % | C35: =C34/C22 -> 0.1673859 | D35: =D34/D22 -> 0.14744881 | E35: =E34/E22 -> 0.13295586 | F35: =F34/F22 -> 0.058274823 | G35: =G34/G22 -> 0.058352097 | H35: =H34/H22 -> 0 | I35: =I34/I22 -> 0 | J35: =J34/J22 -> 1.5859847e-05 | ... L35: =L34/L22 -> 0
B37: Net Profit | C37: =IFERROR(C19+C31-C34,0) -> 758.3 | D37: =IFERROR(D19+D31-D34,0) -> 848.69 | E37: =IFERROR(E19+E31-E34,0) -> 933.81 | F37: =IFERROR(F19+F31-F34,0) -> 2054.66 | G37: =IFERROR(G19+G31-G34,0) -> 2254.74 | H37: =IFERROR(H19+H31-H34,0) -> 3192.09 | I37: =IFERROR(I19+I31-I34,0) -> 4416.13 | J37: =IFERROR(J19+J31-J34,0) -> 6089.83 | ... M37: =IFERROR(M19+M31-M34,0) -> 6452.04
B38: Net Margins % | C38: =C37/C7 -> 0.10927788 | D38: =D37/D7 -> 0.11305782 | E38: =E37/E7 -> 0.10321331 | F38: =F37/F7 -> 0.22171457 | G38: =G37/G7 -> 0.20251689 | H38: =H37/H7 -> 0.23784258 | I38: =I37/I7 -> 0.28002455 | J38: =J37/J7 -> 0.30000079 | ... M38: =M37/M7 -> 0.24126612
B40: No. of Equity shares | C40: =IFERROR('Data Sheet'!B93,0) -> 3.58 | D40: =IFERROR('Data Sheet'!C93,0) -> 4.53 | E40: =IFERROR('Data Sheet'!D93,0) -> 6.53 | F40: =IFERROR('Data Sheet'!E93,0) -> 652.65 | G40: =IFERROR('Data Sheet'!F93,0) -> 938.05 | H40: =IFERROR('Data Sheet'!G93,0) -> 1188.05 | I40: =IFERROR('Data Sheet'!H93,0) -> 1306.85 | J40: =IFERROR('Data Sheet'!I93,0) -> 1306.85 | ... L40: =IFERROR('Data Sheet'!K93,0) -> 1306.85
B42: Earnings per share | C42: =C37/C40 -> 211.81564 | D42: =D37/D40 -> 187.34879 | E42: =E37/E40 -> 143.00306 | F42: =F37/F40 -> 3.1481805 | G42: =G37/G40 -> 2.4036459 | H42: =H37/H40 -> 2.6868314 | I42: =I37/I40 -> 3.3792172 | J42: =J37/J40 -> 4.6599304 | ... L42: =L37/L40 -> 4.9065386
B43: EPS Growth % | D43: =D42/C42-1 -> -0.11551015 | E43: =E42/D42-1 -> -0.23670142 | F43: =F42/E42-1 -> -0.97798522 | G43: =G42/F42-1 -> -0.23649681 | H43: =H42/G42-1 -> 0.11781499 | I43: =I42/H42-1 -> 0.25769605 | J43: =J42/I42-1 -> 0.378997 | K43: =K42/J42-1 -> 0.01269822 | L43: =L42/K42-1 -> 0.039718444
B45: Divident per share | C45: =IFERROR('Data Sheet'!B31/'Historical FS'!C40,0) -> 42.446927 | D45: =IFERROR('Data Sheet'!C31/'Historical FS'!D40,0) -> 74.940397 | E45: =IFERROR('Data Sheet'!D31/'Historical FS'!E40,0) -> 57.168453 | F45: =IFERROR('Data Sheet'!E31/'Historical FS'!F40,0) -> 0.57499425 | G45: =IFERROR('Data Sheet'!F31/'Historical FS'!G40,0) -> 0.42600075 | H45: =IFERROR('Data Sheet'!G31/'Historical FS'!H40,0) -> 0 | I45: =IFERROR('Data Sheet'!H31/'Historical FS'!I40,0) -> 1.0499981 | J45: =IFERROR('Data Sheet'!I31/'Historical FS'!J40,0) -> 1.4 | ... L45: =IFERROR('Data Sheet'!K31/'Historical FS'!L40,0) -> 1.5000038
B46: Divident payout Ratio % | C46: =C45/C42 -> 0.20039562 | D46: =D45/D42 -> 0.40000471 | E46: =E45/E42 -> 0.39977083 | F46: =F45/F42 -> 0.18264336 | G46: =G45/G42 -> 0.17723108 | H46: =H45/H42 -> 0 | I46: =I45/I42 -> 0.31072228 | J46: =J45/J42 -> 0.30043367 | ... L46: =L45/L42 -> 0.30571528
B48: Retained Earnings | C48: =IFERROR(IF(C42>C45,1-C46,0),0) -> 0.79960438 | D48: =IFERROR(IF(D42>D45,1-D46,0),0) -> 0.59999529 | E48: =IFERROR(IF(E42>E45,1-E46,0),0) -> 0.60022917 | F48: =IFERROR(IF(F42>F45,1-F46,0),0) -> 0.81735664 | G48: =IFERROR(IF(G42>G45,1-G46,0),0) -> 0.82276892 | H48: =IFERROR(IF(H42>H45,1-H46,0),0) -> 1 | I48: =IFERROR(IF(I42>I45,1-I46,0),0) -> 0.68927772 | J48: =IFERROR(IF(J42>J45,1-J46,0),0) -> 0.69956633 | ... L48: =IFERROR(IF(L42>L45,1-L46,0),0) -> 0.69428472
A50: # | B50: Balance sheet
B52: Equity Share Capital | C52: =IFERROR('Data Sheet'!B57,0) -> 3583.96 | D52: =IFERROR('Data Sheet'!C57,0) -> 4526.46 | E52: =IFERROR('Data Sheet'!D57,0) -> 6526.46 | F52: =IFERROR('Data Sheet'!E57,0) -> 6526.46 | G52: =IFERROR('Data Sheet'!F57,0) -> 9380.46 | H52: =IFERROR('Data Sheet'!G57,0) -> 11880.46 | I52: =IFERROR('Data Sheet'!H57,0) -> 13068.51 | J52: =IFERROR('Data Sheet'!I57,0) -> 13068.51 | ... L52: =IFERROR('Data Sheet'!K57,0) -> 13068.51
B53: Reserves | C53: =IFERROR('Data Sheet'!B58,0) -> 5097.65 | D53: =IFERROR('Data Sheet'!C58,0) -> 6998.89 | E53: =IFERROR('Data Sheet'!D58,0) -> 5483.14 | F53: =IFERROR('Data Sheet'!E58,0) -> 7402.23 | G53: =IFERROR('Data Sheet'!F58,0) -> 15648.19 | H53: =IFERROR('Data Sheet'!G58,0) -> 18419.29 | I53: =IFERROR('Data Sheet'!H58,0) -> 22844.88 | J53: =IFERROR('Data Sheet'!I58,0) -> 27927.83 | ... L53: =IFERROR('Data Sheet'!K58,0) -> 36110.06
B54: Borrowings | C54: =IFERROR('Data Sheet'!B59,0) -> 71269.63 | D54: =IFERROR('Data Sheet'!C59,0) -> 87503.18 | E54: =IFERROR('Data Sheet'!D59,0) -> 106394.86 | F54: =IFERROR('Data Sheet'!E59,0) -> 134005.53 | G54: =IFERROR('Data Sheet'!F59,0) -> 173932.67 | H54: =IFERROR('Data Sheet'!G59,0) -> 234376.72 | I54: =IFERROR('Data Sheet'!H59,0) -> 323145.26 | J54: =IFERROR('Data Sheet'!I59,0) -> 388439.97 | ... L54: =IFERROR('Data Sheet'!K59,0) -> 412038.52
B55: Other Liabilities | C55: =IFERROR('Data Sheet'!B60,0) -> 7695.75 | D55: =IFERROR('Data Sheet'!C60,0) -> 9371.86 | E55: =IFERROR('Data Sheet'!D60,0) -> 11245.17 | F55: =IFERROR('Data Sheet'!E60,0) -> 13534.1 | G55: =IFERROR('Data Sheet'!F60,0) -> 7642.29 | H55: =IFERROR('Data Sheet'!G60,0) -> 10827.66 | I55: =IFERROR('Data Sheet'!H60,0) -> 21422.87 | J55: =IFERROR('Data Sheet'!I60,0) -> 20543.91 | ... L55: =IFERROR('Data Sheet'!K60,0) -> 23865.34
B56: Total Liabilities | C56: =SUM(C52:C55) -> 87646.99 | D56: =SUM(D52:D55) -> 108400.39 | E56: =SUM(E52:E55) -> 129649.63 | F56: =SUM(F52:F55) -> 161468.32 | G56: =SUM(G52:G55) -> 206603.61 | H56: =SUM(H52:H55) -> 275504.13 | I56: =SUM(I52:I55) -> 380481.52 | J56: =SUM(J52:J55) -> 449980.22 | ... L56: =SUM(L52:L55) -> 485082.43
B58: Fixed Assets Net Block | C58: =IFERROR('Data Sheet'!B62,0) -> 12.01 | D58: =IFERROR('Data Sheet'!C62,0) -> 11.76 | E58: =IFERROR('Data Sheet'!D62,0) -> 11.52 | F58: =IFERROR('Data Sheet'!E62,0) -> 11.29 | G58: =IFERROR('Data Sheet'!F62,0) -> 11.28 | H58: =IFERROR('Data Sheet'!G62,0) -> 11.05 | I58: =IFERROR('Data Sheet'!H62,0) -> 45.36 | J58: =IFERROR('Data Sheet'!I62,0) -> 37.96 | ... L58: =IFERROR('Data Sheet'!K62,0) -> 22.05
B59: Capital Work in Progress | C59: =IFERROR('Data Sheet'!B63,0) -> 0 | D59: =IFERROR('Data Sheet'!C63,0) -> 0 | E59: =IFERROR('Data Sheet'!D63,0) -> 0 | F59: =IFERROR('Data Sheet'!E63,0) -> 0 | G59: =IFERROR('Data Sheet'!F63,0) -> 0 | H59: =IFERROR('Data Sheet'!G63,0) -> 0 | I59: =IFERROR('Data Sheet'!H63,0) -> 0 | J59: =IFERROR('Data Sheet'!I63,0) -> 0 | ... L59: =IFERROR('Data Sheet'!K63,0) -> 3.78
B60: Investments | C60: =IFERROR('Data Sheet'!B64,0) -> 9.32 | D60: =IFERROR('Data Sheet'!C64,0) -> 7.87 | E60: =IFERROR('Data Sheet'!D64,0) -> 7.87 | F60: =IFERROR('Data Sheet'!E64,0) -> 13.98 | G60: =IFERROR('Data Sheet'!F64,0) -> 13.15 | H60: =IFERROR('Data Sheet'!G64,0) -> 11.51 | I60: =IFERROR('Data Sheet'!H64,0) -> 11.98 | J60: =IFERROR('Data Sheet'!I64,0) -> 10 | ... L60: =IFERROR('Data Sheet'!K64,0) -> 53.6
...

Sheet Ratio Analysis
B2: ="Ratio Analysis - "&'Data Sheet'!B1 -> Ratio Analysis - INDIAN RAILWAY FINANCE CORPORATION LTD
B3: Year | C3: ='Data Sheet'!B16 -> 42094 | D3: ='Data Sheet'!C16 -> 42460 | E3: ='Data Sheet'!D16 -> 42825 | F3: ='Data Sheet'!E16 -> 43190 | G3: ='Data Sheet'!F16 -> 43555 | H3: ='Data Sheet'!G16 -> 43921 | I3: ='Data Sheet'!H16 -> 44286 | J3: ='Data Sheet'!I16 -> 44651 | ... L3: ='Data Sheet'!K16 -> 45382 | M3: Trend | N3: Mean | O3: Median
B5: Sales Growth | D5: =IFERROR('Historical FS'!D8,0) -> 0.081781879 | E5: =IFERROR('Historical FS'!E8,0) -> 0.20524226 | F5: =IFERROR('Historical FS'!F8,0) -> 0.024289905 | G5: =IFERROR('Historical FS'!G8,0) -> 0.20140518 | H5: =IFERROR('Historical FS'!H8,0) -> 0.20545305 | I5: =IFERROR('Historical FS'!I8,0) -> 0.17506046 | J5: =IFERROR('Historical FS'!J8,0) -> 0.28717334 | K5: =IFERROR('Historical FS'!K8,0) -> 0.16861155 | L5: =IFERROR('Historical FS'!L8,0) -> 0.1232345 | N5: =IFERROR(AVERAGE(D5:L5),0) -> 0.16358357 | O5: =IFERROR(MEDIAN(C5:L5),0) -> 0.17506046
B6: EBITDA Growth | D6: =IFERROR('Historical FS'!D22/'Historical FS'!C22-1,0) -> 0.0815309 | E6: =IFERROR('Historical FS'!E22/'Historical FS'!D22-1,0) -> 0.20794029 | F6: =IFERROR('Historical FS'!F22/'Historical FS'!E22-1,0) -> 0.023023913 | G6: =IFERROR('Historical FS'!G22/'Historical FS'!F22-1,0) -> 0.20109219 | H6: =IFERROR('Historical FS'!H22/'Historical FS'!G22-1,0) -> 0.20478533 | I6: =IFERROR('Historical FS'!I22/'Historical FS'!H22-1,0) -> 0.17237419 | J6: =IFERROR('Historical FS'!J22/'Historical FS'!I22-1,0) -> 0.28864911 | K6: =IFERROR('Historical FS'!K22/'Historical FS'!J22-1,0) -> 0.16905754 | L6: =IFERROR('Historical FS'!L22/'Historical FS'!K22-1,0) -> 0.12399816 | N6: =IFERROR(AVERAGE(D6:L6),0) -> 0.16360574 | O6: =IFERROR(MEDIAN(C6:L6),0) -> 0.17237419
B7: EBT Growth | D7: =IFERROR('Historical FS'!D31/'Historical FS'!C31-1,0) -> 0.018863585 | E7: =IFERROR('Historical FS'!E31/'Historical FS'!D31-1,0) -> 0.094244088 | F7: =IFERROR('Historical FS'!F31/'Historical FS'!E31-1,0) -> 0.21483725 | G7: =IFERROR('Historical FS'!G31/'Historical FS'!F31-1,0) -> 0.11976413 | H7: =IFERROR('Historical FS'!H31/'Historical FS'!G31-1,0) -> 0.10009305 | I7: =IFERROR('Historical FS'!I31/'Historical FS'!H31-1,0) -> 0.38338299 | J7: =IFERROR('Historical FS'!J31/'Historical FS'!I31-1,0) -> 0.37866978 | K7: =IFERROR('Historical FS'!K31/'Historical FS'!J31-1,0) -> 0.0063354868 | L7: =IFERROR('Historical FS'!L31/'Historical FS'!K31-1,0) -> 0.044919612 | N7: =IFERROR(AVERAGE(D7:L7),0) -> 0.15123444 | O7: =IFERROR(MEDIAN(C7:L7),0) -> 0.10009305
B8: Net profit Growth | D8: =IFERROR('Historical FS'!D37/'Historical FS'!C37-1,0) -> 0.11920084 | E8: =IFERROR('Historical FS'!E37/'Historical FS'!D37-1,0) -> 0.10029575 | F8: =IFERROR('Historical FS'!F37/'Historical FS'!E37-1,0) -> 1.2002977 | G8: =IFERROR('Historical FS'!G37/'Historical FS'!F37-1,0) -> 0.097378642 | H8: =IFERROR('Historical FS'!H37/'Historical FS'!G37-1,0) -> 0.41572421 | I8: =IFERROR('Historical FS'!I37/'Historical FS'!H37-1,0) -> 0.38346037 | J8: =IFERROR('Historical FS'!J37/'Historical FS'!I37-1,0) -> 0.378997 | K8: =IFERROR('Historical FS'!K37/'Historical FS'!J37-1,0) -> 0.01269822 | L8: =IFERROR('Historical FS'!L37/'Historical FS'!K37-1,0) -> 0.039718444 | N8: =IFERROR(AVERAGE(D8:L8),0) -> 0.30530791 | O8: =IFERROR(MEDIAN(C8:L8),0) -> 0.11920084
B9: EPS Growth | D9: ='Historical FS'!D43 -> -0.11551015 | E9: ='Historical FS'!E43 -> -0.23670142 | F9: ='Historical FS'!F43 -> -0.97798522 | G9: ='Historical FS'!G43 -> -0.23649681 | H9: ='Historical FS'!H43 -> 0.11781499 | I9: ='Historical FS'!I43 -> 0.25769605 | J9: ='Historical FS'!J43 -> 0.378997 | K9: ='Historical FS'!K43 -> 0.01269822 | L9: ='Historical FS'!L43 -> 0.039718444 | N9: =IFERROR(AVERAGE(D9:L9),0) -> -0.084418767 | O9: =IFERROR(MEDIAN(C9:L9),0) -> 0.01269822
B11: Gross Margin | C11: =IFERROR('Historical FS'!C14,0) -> 0.999523 | D11: =IFERROR('Historical FS'!D14,0) -> 0.99942851 | E11: =IFERROR('Historical FS'!E14,0) -> 0.9996441 | F11: =IFERROR('Historical FS'!F14,0) -> 0.99937737 | G11: =IFERROR('Historical FS'!G14,0) -> 0.99939912 | H11: =IFERROR('Historical FS'!H14,0) -> 0.99934133 | I11: =IFERROR('Historical FS'!I14,0) -> 0.99931074 | J11: =IFERROR('Historical FS'!J14,0) -> 0.99924727 | ... L11: =IFERROR('Historical FS'!L14,0) -> 0.99941604 | N11: =IFERROR(AVERAGE(C11:L11),0) -> 0.9993954 | O11: =IFERROR(MEDIAN(C11:L11),0) -> 0.99938824
B12: EBITDA Margin | C12: =IFERROR('Historical FS'!C23,0) -> 0.99514208 | D12: =IFERROR('Historical FS'!D23,0) -> 0.99491121 | E12: =IFERROR('Historical FS'!E23,0) -> 0.9971384 | F12: =IFERROR('Historical FS'!F23,0) -> 0.99590596 | G12: =IFERROR('Historical FS'!G23,0) -> 0.99564651 | H12: =IFERROR('Historical FS'!H23,0) -> 0.99509501 | I12: =IFERROR('Historical FS'!I23,0) -> 0.99282014 | J12: =IFERROR('Historical FS'!J23,0) -> 0.99395844 | ... L12: =IFERROR('Historical FS'!L23,0) -> 0.99501379 | N12: =IFERROR(AVERAGE(C12:L12),0) -> 0.99499693 | O12: =IFERROR(MEDIAN(C12:L12),0) -> 0.9950544
B13: EBIT Margin | C13: =IFERROR(('Historical FS'!C22-'Historical FS'!C28)/'Historical FS'!C7,0) -> 0.99507868 | D13: =IFERROR(('Historical FS'!D22-'Historical FS'!D28)/'Historical FS'!D7,0) -> 0.99486458 | E13: =IFERROR(('Historical FS'!E22-'Historical FS'!E28)/'Historical FS'!E7,0) -> 0.99709971 | F13: =IFERROR(('Historical FS'!F22-'Historical FS'!F28)/'Historical FS'!F7,0) -> 0.9958682 | G13: =IFERROR(('Historical FS'!G22-'Historical FS'!G28)/'Historical FS'!G7,0) -> 0.99560878 | H13: =IFERROR(('Historical FS'!H22-'Historical FS'!H28)/'Historical FS'!H7,0) -> 0.99506073 | I13: =IFERROR(('Historical FS'!I22-'Historical FS'!I28)/'Historical FS'!I7,0) -> 0.99253924 | J13: =IFERROR(('Historical FS'!J22-'Historical FS'!J28)/'Historical FS'!J7,0) -> 0.99326728 | ... L13: =IFERROR(('Historical FS'!L22-'Historical FS'!L28)/'Historical FS'!L7,0) -> 0.9946595 | N13: =IFERROR(AVERAGE(C13:L13),0) -> 0.99477918 | O13: =IFERROR(MEDIAN(C13:L13),0) -> 0.99496266
B14: EBT Margin | C14: =IFERROR('Historical FS'!C32,0) -> 0.27571085 | D14: =IFERROR('Historical FS'!D32,0) -> 0.25967504 | E14: =IFERROR('Historical FS'!E32,0) -> 0.23575997 | F14: =IFERROR('Historical FS'!F32,0) -> 0.27961809 | G14: =IFERROR('Historical FS'!G32,0) -> 0.26061675 | H14: =IFERROR('Historical FS'!H32,0) -> 0.23783811 | I14: =IFERROR('Historical FS'!I32,0) -> 0.28000363 | J14: =IFERROR('Historical FS'!J32,0) -> 0.29990719 | ... L14: =IFERROR('Historical FS'!L32,0) -> 0.24025472 | N14: =IFERROR(AVERAGE(C14:L14),0) -> 0.26276457 | O14: =IFERROR(MEDIAN(C14:L14),0) -> 0.26014589
B15: Net profit Margin | C15: =IFERROR('Historical FS'!C38,0) -> 0.10927788 | D15: =IFERROR('Historical FS'!D38,0) -> 0.11305782 | E15: =IFERROR('Historical FS'!E38,0) -> 0.10321331 | F15: =IFERROR('Historical FS'!F38,0) -> 0.22171457 | G15: =IFERROR('Historical FS'!G38,0) -> 0.20251689 | H15: =IFERROR('Historical FS'!H38,0) -> 0.23784258 | I15: =IFERROR('Historical FS'!I38,0) -> 0.28002455 | J15: =IFERROR('Historical FS'!J38,0) -> 0.30000079 | ... L15: =IFERROR('Historical FS'!L38,0) -> 0.24064541 | N15: =IFERROR(AVERAGE(C15:L15),0) -> 0.20682692 | O15: =IFERROR(MEDIAN(C15:L15),0) -> 0.22977858
B17: Sales expense % Sales | C17: =IFERROR('Historical FS'!C17,0) -> 0.0043809148 | D17: =IFERROR('Historical FS'!D17,0) -> 0.0045173039 | E17: =IFERROR('Historical FS'!E17,0) -> 0.0025056978 | F17: =IFERROR('Historical FS'!F17,0) -> 0.0034714054 | G17: =IFERROR('Historical FS'!G17,0) -> 0.0037526081 | H17: =IFERROR('Historical FS'!H17,0) -> 0.004246324 | I17: =IFERROR('Historical FS'!I17,0) -> 0.0064905954 | J17: =IFERROR('Historical FS'!J17,0) -> 0.0052888315 | ... L17: =IFERROR('Historical FS'!L17,0) -> 0.0044022492 | N17: =IFERROR(AVERAGE(C17:L17),0) -> 0.004398467 | O17: =IFERROR(MEDIAN(C17:L17),0) -> 0.004391582
B18: Depreciation % Sales | C18: =IFERROR('Historical FS'!C29,0) -> 6.3407977e-05 | D18: =IFERROR('Historical FS'!D29,0) -> 4.6625077e-05 | E18: =IFERROR('Historical FS'!E29,0) -> 3.8685233e-05 | F18: =IFERROR('Historical FS'!F29,0) -> 3.7767855e-05 | G18: =IFERROR('Historical FS'!G29,0) -> 3.7723681e-05 | H18: =IFERROR('Historical FS'!H29,0) -> 3.4274593e-05 | I18: =IFERROR('Historical FS'!I29,0) -> 0.00028090404 | J18: =IFERROR('Historical FS'!J29,0) -> 0.00069115411 | ... L18: =IFERROR('Historical FS'!L29,0) -> 0.00035428161 | N18: =IFERROR(AVERAGE(C18:L18),0) -> 0.00021775207 | O18: =IFERROR(MEDIAN(C18:L18),0) -> 5.5016527e-05
B19: Operating income % Sales | C19: =C13 -> 0.99507868 | D19: =D13 -> 0.99486458 | E19: =E13 -> 0.99709971 | F19: =F13 -> 0.9958682 | G19: =G13 -> 0.99560878 | H19: =H13 -> 0.99506073 | I19: =I13 -> 0.99253924 | J19: =J13 -> 0.99326728 | ... L19: =L13 -> 0.9946595 | N19: =IFERROR(AVERAGE(C19:L19),0) -> 0.99477918 | O19: =IFERROR(MEDIAN(C19:L19),0) -> 0.99496266
B21: Return on capital employed | C21: =IFERROR(('Historical FS'!C22-'Historical FS'!C28)/SUM('Historical FS'!C52:C54),0) -> 0.08636564 | D21: =IFERROR(('Historical FS'!D22-'Historical FS'!D28)/SUM('Historical FS'!D52:D54),0) -> 0.075414025 | E21: =IFERROR(('Historical FS'!E22-'Historical FS'!E28)/SUM('Historical FS'!E52:E54),0) -> 0.076189191 | F21: =IFERROR(('Historical FS'!F22-'Historical FS'!F28)/SUM('Historical FS'!F52:F54),0) -> 0.062384822 | G21: =IFERROR(('Historical FS'!G22-'Historical FS'!G28)/SUM('Historical FS'!G52:G54),0) -> 0.055712839 | H21: =IFERROR(('Historical FS'!H22-'Historical FS'!H28)/SUM('Historical FS'!H52:H54),0) -> 0.050456809 | I21: =IFERROR(('Historical FS'!I22-'Historical FS'!I28)/SUM('Historical FS'!I52:I54),0) -> 0.043594131 | J21: =IFERROR(('Historical FS'!J22-'Historical FS'!J28)/SUM('Historical FS'!J52:J54),0) -> 0.046951572 | ... L21: =IFERROR(('Historical FS'!L22-'Historical FS'!L28)/SUM('Historical FS'!L52:L54),0) -> 0.057463547 | N21: =IFERROR(AVERAGE(C21:L21),0) -> 0.060538017 | O21: =IFERROR(MEDIAN(C21:L21),0) -> 0.056588193
B22: Retained earnings | C22: =IFERROR('Historical FS'!C48,0) -> 0.79960438 | D22: =IFERROR('Historical FS'!D48,0) -> 0.59999529 | E22: =IFERROR('Historical FS'!E48,0) -> 0.60022917 | F22: =IFERROR('Historical FS'!F48,0) -> 0.81735664 | G22: =IFERROR('Historical FS'!G48,0) -> 0.82276892 | H22: =IFERROR('Historical FS'!H48,0) -> 1 | I22: =IFERROR('Historical FS'!I48,0) -> 0.68927772 | J22: =IFERROR('Historical FS'!J48,0) -> 0.69956633 | ... L22: =IFERROR('Historical FS'!L48,0) -> 0.69428472 | N22: =IFERROR(AVERAGE(C22:L22),0) -> 0.74052253 | O22: =IFERROR(MEDIAN(C22:L22),0) -> 0.69692552
B23: Return on equity | C23: =IFERROR('Historical FS'!C37/SUM('Historical FS'!C52:C53),0) -> 0.08734555 | D23: =IFERROR('Historical FS'!D37/SUM('Historical FS'!D52:D53),0) -> 0.073636809 | E23: =IFERROR('Historical FS'!E37/SUM('Historical FS'!E52:E53),0) -> 0.077755296 | F23: =IFERROR('Historical FS'!F37/SUM('Historical FS'!F52:F53),0) -> 0.1475128 | G23: =IFERROR('Historical FS'!G37/SUM('Historical FS'!G52:G53),0) -> 0.090086361 | H23: =IFERROR('Historical FS'!H37/SUM('Historical FS'!H52:H53),0) -> 0.10535037 | I23: =IFERROR('Historical FS'!I37/SUM('Historical FS'!I52:I53),0) -> 0.12296611 | J23: =IFERROR('Historical FS'!J37/SUM('Historical FS'!J52:J53),0) -> 0.1485457 | ... L23: =IFERROR('Historical FS'!L37/SUM('Historical FS'!L52:L53),0) -> 0.13038423 | N23: =IFERROR(AVERAGE(C23:L23),0) -> 0.11216122 | O23: =IFERROR(MEDIAN(C23:L23),0) -> 0.11415824
B24: Self sustainable growth rate | C24: =IFERROR(C22*C23,0) -> 0.069841884 | D24: =IFERROR(D22*D23,0) -> 0.044181739 | E24: =IFERROR(E22*E23,0) -> 0.046670997 | F24: =IFERROR(F22*F23,0) -> 0.12057056 | G24: =IFERROR(G22*G23,0) -> 0.074120258 | H24: =IFERROR(H22*H23,0) -> 0.10535037 | I24: =IFERROR(I22*I23,0) -> 0.084757802 | J24: =IFERROR(J22*J23,0) -> 0.10391757 | ... L24: =IFERROR(L22*L23,0) -> 0.090523779 | N24: =IFERROR(AVERAGE(C24:L24),0) -> 0.083409034 | O24: =IFERROR(MEDIAN(C24:L24),0) -> 0.08764079
B25: Interest coverage ratio | C25: =IFERROR(('Historical FS'!C22-'Historical FS'!C28)/'Historical FS'!C25,0) -> 1.3832683 | D25: =IFERROR(('Historical FS'!D22-'Historical FS'!D28)/'Historical FS'!D25,0) -> 1.3532083 | E25: =IFERROR(('Historical FS'!E22-'Historical FS'!E28)/'Historical FS'!E25,0) -> 1.3096646 | F25: =IFERROR(('Historical FS'!F22-'Historical FS'!F28)/'Historical FS'!F25,0) -> 1.3903917 | G25: =IFERROR(('Historical FS'!G22-'Historical FS'!G28)/'Historical FS'!G25,0) -> 1.3545844 | H25: =IFERROR(('Historical FS'!H22-'Historical FS'!H28)/'Historical FS'!H25,0) -> 1.3140927 | I25: =IFERROR(('Historical FS'!I22-'Historical FS'!I28)/'Historical FS'!I25,0) -> 1.3929679 | J25: =IFERROR(('Historical FS'!J22-'Historical FS'!J28)/'Historical FS'!J25,0) -> 1.4325418 | ... L25: =IFERROR(('Historical FS'!L22-'Historical FS'!L28)/'Historical FS'!L25,0) -> 1.3184692 | N25: =IFERROR(AVERAGE(C25:L25),0) -> 1.3600334 | O25: =IFERROR(MEDIAN(C25:L25),0) -> 1.3538964
B27: Debtor turnover ratio | C27: =IFERROR('Historical FS'!C7/'Historical FS'!C64,0) -> 0 | D27: =IFERROR('Historical FS'!D7/'Historical FS'!D64,0) -> 0 | E27: =IFERROR('Historical FS'!E7/'Historical FS'!E64,0) -> 0 | F27: =IFERROR('Historical FS'!F7/'Historical FS'!F64,0) -> 0 | G27: =IFERROR('Historical FS'!G7/'Historical FS'!G64,0) -> 0 | H27: =IFERROR('Historical FS'!H7/'Historical FS'!H64,0) -> 0 | I27: =IFERROR('Historical FS'!I7/'Historical FS'!I64,0) -> 0 | J27: =IFERROR('Historical FS'!J7/'Historical FS'!J64,0) -> 0.10114668 | ... L27: =IFERROR('Historical FS'!L7/'Historical FS'!L64,0) -> 0.10260468 | N27: =IFERROR(AVERAGE(C27:L27),0) -> 0.030122997 | O27: =IFERROR(MEDIAN(C27:L27),0) -> 0
B28: Creditor turnover ratio | C28: =IFERROR('Historical FS'!C7/'Historical FS'!C55,0) -> 0.90169119 | D28: =IFERROR('Historical FS'!D7/'Historical FS'!D55,0) -> 0.80098188 | E28: =IFERROR('Historical FS'!E7/'Historical FS'!E55,0) -> 0.80455698 | F28: =IFERROR('Historical FS'!F7/'Historical FS'!F55,0) -> 0.68472525 | G28: =IFERROR('Historical FS'!G7/'Historical FS'!G55,0) -> 1.4568395 | H28: =IFERROR('Historical FS'!H7/'Historical FS'!H55,0) -> 1.2395125 | I28: =IFERROR('Historical FS'!I7/'Historical FS'!I55,0) -> 0.736153 | J28: =IFERROR('Historical FS'!J7/'Historical FS'!J55,0) -> 0.9880972 | ... L28: =IFERROR('Historical FS'!L7/'Historical FS'!L55,0) -> 1.1164924 | N28: =IFERROR(AVERAGE(C28:L28),0) -> 0.96160672 | O28: =IFERROR(MEDIAN(C28:L28),0) -> 0.89435426
B29: Inventory turnover ratio | C29: =IFERROR('Historical FS'!C7/'Historical FS'!C65,0) -> 0 | D29: =IFERROR('Historical FS'!D7/'Historical FS'!D65,0) -> 0 | E29: =IFERROR('Historical FS'!E7/'Historical FS'!E65,0) -> 0 | F29: =IFERROR('Historical FS'!F7/'Historical FS'!F65,0) -> 0 | G29: =IFERROR('Historical FS'!G7/'Historical FS'!G65,0) -> 0 | H29: =IFERROR('Historical FS'!H7/'Historical FS'!H65,0) -> 0 | I29: =IFERROR('Historical FS'!I7/'Historical FS'!I65,0) -> 0 | J29: =IFERROR('Historical FS'!J7/'Historical FS'!J65,0) -> 0 | ... L29: =IFERROR('Historical FS'!L7/'Historical FS'!L65,0) -> 0 | N29: =IFERROR(AVERAGE(C29:L29),0) -> 0 | O29: =IFERROR(MEDIAN(C29:L29),0) -> 0
B30: Fixed Asset turnover ratio | C30: =IFERROR('Historical FS'!C7/'Historical FS'!C58,0) -> 577.78435 | D30: =IFERROR('Historical FS'!D7/'Historical FS'!D58,0) -> 638.32398 | E30: =IFERROR('Historical FS'!E7/'Historical FS'!E58,0) -> 785.36285 | F30: =IFERROR('Historical FS'!F7/'Historical FS'!F58,0) -> 820.82728 | G30: =IFERROR('Historical FS'!G7/'Historical FS'!G58,0) -> 987.02039 | H30: =IFERROR('Historical FS'!H7/'Historical FS'!H58,0) -> 1214.5719 | I30: =IFERROR('Historical FS'!I7/'Historical FS'!I58,0) -> 347.67438 | J30: =IFERROR('Historical FS'!J7/'Historical FS'!J58,0) -> 534.75711 | ... L30: =IFERROR('Historical FS'!L7/'Historical FS'!L58,0) -> 1208.4113 | N30: =IFERROR(AVERAGE(C30:L30),0) -> 835.0903 | O30: =IFERROR(MEDIAN(C30:L30),0) -> 803.09506
B31: Capital turnover ratio | C31: =IFERROR('Historical FS'!C7/SUM('Historical FS'!C52:C53),0) -> 0.7992976 | D31: =IFERROR('Historical FS'!D7/SUM('Historical FS'!D52:D53),0) -> 0.65131992 | E31: =IFERROR('Historical FS'!E7/SUM('Historical FS'!E52:E53),0) -> 0.75334566 | F31: =IFERROR('Historical FS'!F7/SUM('Historical FS'!F52:F53),0) -> 0.66532746 | G31: =IFERROR('Historical FS'!G7/SUM('Historical FS'!G52:G53),0) -> 0.44483382 | H31: =IFERROR('Historical FS'!H7/SUM('Historical FS'!H52:H53),0) -> 0.44294161 | I31: =IFERROR('Historical FS'!I7/SUM('Historical FS'!I52:I53),0) -> 0.43912619 | J31: =IFERROR('Historical FS'!J7/SUM('Historical FS'!J52:J53),0) -> 0.49515103 | ... L31: =IFERROR('Historical FS'!L7/SUM('Historical FS'!L52:L53),0) -> 0.54181059 | N31: =IFERROR(AVERAGE(C31:L31),0) -> 0.57640847 | O31: =IFERROR(MEDIAN(C31:L31),0) -> 0.53637071
B33: Debtor Days | C33: =IFERROR(365/C27,0) -> 0 | D33: =IFERROR(365/D27,0) -> 0 | E33: =IFERROR(365/E27,0) -> 0 | F33: =IFERROR(365/F27,0) -> 0 | G33: =IFERROR(365/G27,0) -> 0 | H33: =IFERROR(365/H27,0) -> 0 | I33: =IFERROR(365/I27,0) -> 0 | J33: =IFERROR(365/J27,0) -> 3608.6207 | ... L33: =IFERROR(365/L27,0) -> 3557.3427 | N33: =IFERROR(AVERAGE(C33:L33),0) -> 1091.0375 | O33: =IFERROR(MEDIAN(C33:L33),0) -> 0
B34: Payable Days | C34: =IFERROR(365/C28,0) -> 404.7949 | D34: =IFERROR(365/D28,0) -> 455.69071 | E34: =IFERROR(365/E28,0) -> 453.66582 | F34: =IFERROR(365/F28,0) -> 533.06052 | G34: =IFERROR(365/G28,0) -> 250.54235 | H34: =IFERROR(365/H28,0) -> 294.47061 | I34: =IFERROR(365/I28,0) -> 495.82084 | J34: =IFERROR(365/J28,0) -> 369.39686 | ... L34: =IFERROR(365/L28,0) -> 326.9167 | N34: =IFERROR(AVERAGE(C34:L34),0) -> 399.58507 | O34: =IFERROR(MEDIAN(C34:L34),0) -> 408.14315
B35: Inventory Days | C35: =IFERROR(365/C29,0) -> 0 | D35: =IFERROR(365/D29,0) -> 0 | E35: =IFERROR(365/E29,0) -> 0 | F35: =IFERROR(365/F29,0) -> 0 | G35: =IFERROR(365/G29,0) -> 0 | H35: =IFERROR(365/H29,0) -> 0 | I35: =IFERROR(365/I29,0) -> 0 | J35: =IFERROR(365/J29,0) -> 0 | ... L35: =IFERROR(365/L29,0) -> 0 | N35: =IFERROR(AVERAGE(C35:L35),0) -> 0 | O35: =IFERROR(MEDIAN(C35:L35),0) -> 0
B36: Cash Cycle Convertion | C36: =IFERROR(SUM(C33,C35)-C34,0) -> -404.7949 | D36: =IFERROR(SUM(D33,D35)-D34,0) -> -455.69071 | E36: =IFERROR(SUM(E33,E35)-E34,0) -> -453.66582 | F36: =IFERROR(SUM(F33,F35)-F34,0) -> -533.06052 | G36: =IFERROR(SUM(G33,G35)-G34,0) -> -250.54235 | H36: =IFERROR(SUM(H33,H35)-H34,0) -> -294.47061 | I36: =IFERROR(SUM(I33,I35)-I34,0) -> -495.82084 | J36: =IFERROR(SUM(J33,J35)-J34,0) -> 3239.2238 | ... L36: =IFERROR(SUM(L33,L35)-L34,0) -> 3230.426 | N36: =IFERROR(AVERAGE(C36:L36),0) -> 691.45238 | O36: =IFERROR(MEDIAN(C36:L36),0) -> -349.63276
B38: CFO/Sales | C38: =IFERROR('Historical FS'!C75/'Historical FS'!C7,0) -> 0 | D38: =IFERROR('Historical FS'!D75/'Historical FS'!D7,0) -> -2.1817206 | E38: =IFERROR('Historical FS'!E75/'Historical FS'!E7,0) -> -2.1503662 | F38: =IFERROR('Historical FS'!F75/'Historical FS'!F7,0) -> -3.0296424 | G38: =IFERROR('Historical FS'!G75/'Historical FS'!G7,0) -> -3.749751 | H38: =IFERROR('Historical FS'!H75/'Historical FS'!H7,0) -> -4.6718215 | I38: =IFERROR('Historical FS'!I75/'Historical FS'!I7,0) -> -5.7009348 | J38: =IFERROR('Historical FS'!J75/'Historical FS'!J7,0) -> -3.1731156 | ... L38: =IFERROR('Historical FS'!L75/'Historical FS'!L7,0) -> 0.29701484 | N38: =IFERROR(AVERAGE(C38:L38),0) -> -2.5565474 | O38: =IFERROR(MEDIAN(C38:L38),0) -> -2.6056815
B39: CFO/Total Assets | C39: =IFERROR('Historical FS'!C75/'Historical FS'!C69,0) -> 0 | D39: =IFERROR('Historical FS'!D75/'Historical FS'!D69,0) -> -0.1510834 | E39: =IFERROR('Historical FS'!E75/'Historical FS'!E69,0) -> -0.15005966 | F39: =IFERROR('Historical FS'!F75/'Historical FS'!F69,0) -> -0.17388005 | G39: =IFERROR('Historical FS'!G75/'Historical FS'!G69,0) -> -0.20206902 | H39: =IFERROR('Historical FS'!H75/'Historical FS'!H69,0) -> -0.22758501 | I39: =IFERROR('Historical FS'!I75/'Historical FS'!I69,0) -> -0.23629702 | J39: =IFERROR('Historical FS'!J75/'Historical FS'!J69,0) -> -0.14314469 | ... L39: =IFERROR('Historical FS'!L75/'Historical FS'!L69,0) -> 0.016314959 | N39: =IFERROR(AVERAGE(C39:L39),0) -> -0.13261048 | O39: =IFERROR(MEDIAN(C39:L39),0) -> -0.15057153
B40: CFO/Debt | C40: =IFERROR('Historical FS'!C75/'Historical FS'!C54,0) -> 0 | D40: =IFERROR('Historical FS'!D75/'Historical FS'!D54,0) -> -0.18716463 | E40: =IFERROR('Historical FS'!E75/'Historical FS'!E54,0) -> -0.18285827 | F40: =IFERROR('Historical FS'!F75/'Historical FS'!F54,0) -> -0.20951464 | G40: =IFERROR('Historical FS'!G75/'Historical FS'!G54,0) -> -0.24002501 | H40: =IFERROR('Historical FS'!H75/'Historical FS'!H54,0) -> -0.26752064 | I40: =IFERROR('Historical FS'!I75/'Historical FS'!I54,0) -> -0.27822364 | J40: =IFERROR('Historical FS'!J75/'Historical FS'!J54,0) -> -0.165823 | ... L40: =IFERROR('Historical FS'!L75/'Historical FS'!L54,0) -> 0.019207185 | N40: =IFERROR(AVERAGE(C40:L40),0) -> -0.15801632 | O40: =IFERROR(MEDIAN(C40:L40),0) -> -0.18501145

Sheet Common-size statements
B2: ="Common-Size Income Statement"&" - "&'Data Sheet'!$B$1 -> Common-Size Income Statement - INDIAN RAILWAY FINANCE CORPORATION LTD
B4: Particulars | C4: ='Data Sheet'!C$16 -> 42460 | D4: ='Data Sheet'!D$16 -> 42825 | E4: ='Data Sheet'!E$16 -> 43190 | F4: ='Data Sheet'!F$16 -> 43555 | G4: ='Data Sheet'!G$16 -> 43921 | H4: ='Data Sheet'!H$16 -> 44286 | I4: ='Data Sheet'!I$16 -> 44651 | J4: ='Data Sheet'!J$16 -> 45016 | K4: ='Data Sheet'!K$16 -> 45382
B6: ='Data Sheet'!A17 -> Sales | C6: ='Data Sheet'!C17/'Data Sheet'!C$17 -> 1 | D6: ='Data Sheet'!D17/'Data Sheet'!D$17 -> 1 | E6: ='Data Sheet'!E17/'Data Sheet'!E$17 -> 1 | F6: ='Data Sheet'!F17/'Data Sheet'!F$17 -> 1 | G6: ='Data Sheet'!G17/'Data Sheet'!G$17 -> 1 | H6: ='Data Sheet'!H17/'Data Sheet'!H$17 -> 1 | I6: ='Data Sheet'!I17/'Data Sheet'!I$17 -> 1 | J6: ='Data Sheet'!J17/'Data Sheet'!J$17 -> 1 | K6: ='Data Sheet'!K17/'Data Sheet'!K$17 -> 1
B7: ='Data Sheet'!A18 -> Raw Material Cost | C7: ='Data Sheet'!C18/'Data Sheet'!C$17 -> 0 | D7: ='Data Sheet'!D18/'Data Sheet'!D$17 -> 0 | E7: ='Data Sheet'!E18/'Data Sheet'!E$17 -> 0 | F7: ='Data Sheet'!F18/'Data Sheet'!F$17 -> 0 | G7: ='Data Sheet'!G18/'Data Sheet'!G$17 -> 0 | H7: ='Data Sheet'!H18/'Data Sheet'!H$17 -> 0 | I7: ='Data Sheet'!I18/'Data Sheet'!I$17 -> 0 | J7: ='Data Sheet'!J18/'Data Sheet'!J$17 -> 0 | K7: ='Data Sheet'!K18/'Data Sheet'!K$17 -> 0
B8: ='Data Sheet'!A19 -> Change in Inventory | C8: ='Data Sheet'!C19/'Data Sheet'!C$17 -> 0 | D8: ='Data Sheet'!D19/'Data Sheet'!D$17 -> 0 | E8: ='Data Sheet'!E19/'Data Sheet'!E$17 -> 0 | F8: ='Data Sheet'!F19/'Data Sheet'!F$17 -> 0 | G8: ='Data Sheet'!G19/'Data Sheet'!G$17 -> 0 | H8: ='Data Sheet'!H19/'Data Sheet'!H$17 -> 0 | I8: ='Data Sheet'!I19/'Data Sheet'!I$17 -> 0 | J8: ='Data Sheet'!J19/'Data Sheet'!J$17 -> 0 | K8: ='Data Sheet'!K19/'Data Sheet'!K$17 -> 0
B9: ='Data Sheet'!A20 -> Power and Fuel | C9: ='Data Sheet'!C20/'Data Sheet'!C$17 -> 2.6642901e-05 | D9: ='Data Sheet'!D20/'Data Sheet'!D$17 -> 2.4316432e-05 | E9: ='Data Sheet'!E20/'Data Sheet'!E$17 -> 2.5897958e-05 | F9: ='Data Sheet'!F20/'Data Sheet'!F$17 -> 1.9760023e-05 | G9: ='Data Sheet'!G20/'Data Sheet'!G$17 -> 1.9372596e-05 | H9: ='Data Sheet'!H20/'Data Sheet'!H$17 -> 1.5218278e-05 | I9: ='Data Sheet'!I20/'Data Sheet'!I$17 -> 1.0345144e-05 | J9: ='Data Sheet'!J20/'Data Sheet'!J$17 -> 9.6956044e-06 | K9: ='Data Sheet'!K20/'Data Sheet'!K$17 -> 9.3824579e-06
B10: ='Data Sheet'!A21 -> Other Mfr. Exp | C10: ='Data Sheet'!C21/'Data Sheet'!C$17 -> 0 | D10: ='Data Sheet'!D21/'Data Sheet'!D$17 -> 0 | E10: ='Data Sheet'!E21/'Data Sheet'!E$17 -> 0 | F10: ='Data Sheet'!F21/'Data Sheet'!F$17 -> 0 | G10: ='Data Sheet'!G21/'Data Sheet'!G$17 -> 0.00015498077 | H10: ='Data Sheet'!H21/'Data Sheet'!H$17 -> 0.00016613286 | I10: ='Data Sheet'!I21/'Data Sheet'!I$17 -> 0.00019458722 | J10: ='Data Sheet'!J21/'Data Sheet'!J$17 -> 0.00016524682 | K10: ='Data Sheet'!K21/'Data Sheet'!K$17 -> 0.00014899343
B11: ='Data Sheet'!A22 -> Employee Cost | C11: ='Data Sheet'!C22/'Data Sheet'!C$17 -> 0.00054484733 | D11: ='Data Sheet'!D22/'Data Sheet'!D$17 -> 0.00033158771 | E11: ='Data Sheet'!E22/'Data Sheet'!E$17 -> 0.00059673211 | F11: ='Data Sheet'!F22/'Data Sheet'!F$17 -> 0.00058112433 | G11: ='Data Sheet'!G22/'Data Sheet'!G$17 -> 0.0004843149 | H11: ='Data Sheet'!H22/'Data Sheet'!H$17 -> 0.00050791002 | I11: ='Data Sheet'!I22/'Data Sheet'!I$17 -> 0.00054779998 | J11: ='Data Sheet'!J22/'Data Sheet'!J$17 -> 0.00055855112 | K11: ='Data Sheet'!K22/'Data Sheet'!K$17 -> 0.00042558829
B12: ='Data Sheet'!A23 -> Selling and admin | C12: ='Data Sheet'!C23/'Data Sheet'!C$17 -> 0.0044133966 | D12: ='Data Sheet'!D23/'Data Sheet'!D$17 -> 0.0024294326 | E12: ='Data Sheet'!E23/'Data Sheet'!E$17 -> 0.00074888261 | F12: ='Data Sheet'!F23/'Data Sheet'!F$17 -> 0.00042034959 | G12: ='Data Sheet'!G23/'Data Sheet'!G$17 -> 0.00030400074 | H12: ='Data Sheet'!H23/'Data Sheet'!H$17 -> 0.00031958383 | I12: ='Data Sheet'!I23/'Data Sheet'!I$17 -> 0.00033843398 | J12: ='Data Sheet'!J23/'Data Sheet'!J$17 -> 0.00034271854 | K12: ='Data Sheet'!K23/'Data Sheet'!K$17 -> 0.00026983949
B13: ='Data Sheet'!A24 -> Other Expenses | C13: ='Data Sheet'!C24/'Data Sheet'!C$17 -> 0.00010390731 | D13: ='Data Sheet'!D24/'Data Sheet'!D$17 -> 7.6265173e-05 | E13: ='Data Sheet'!E24/'Data Sheet'!E$17 -> 0.0027225228 | F13: ='Data Sheet'!F24/'Data Sheet'!F$17 -> 0.0033322585 | G13: ='Data Sheet'!G24/'Data Sheet'!G$17 -> 0.0039423233 | H13: ='Data Sheet'!H24/'Data Sheet'!H$17 -> 0.0061710116 | I13: ='Data Sheet'!I24/'Data Sheet'!I$17 -> 0.0049503975 | J13: ='Data Sheet'!J24/'Data Sheet'!J$17 -> 0.0045860209 | K13: ='Data Sheet'!K24/'Data Sheet'!K$17 -> 0.0041324097
B14: ='Data Sheet'!A25 -> Other Income | C14: ='Data Sheet'!C25/'Data Sheet'!C$17 -> 8.1260849e-05 | D14: ='Data Sheet'!D25/'Data Sheet'!D$17 -> 2.8737601e-05 | E14: ='Data Sheet'!E25/'Data Sheet'!E$17 -> 0.00013272703 | F14: ='Data Sheet'!F25/'Data Sheet'!F$17 -> -1.7963658e-06 | G14: ='Data Sheet'!G25/'Data Sheet'!G$17 -> 4.4705991e-06 | H14: ='Data Sheet'!H25/'Data Sheet'!H$17 -> 2.0925132e-05 | I14: ='Data Sheet'!I25/'Data Sheet'!I$17 -> 0.00010936295 | J14: ='Data Sheet'!J25/'Data Sheet'!J$17 -> 0.0017140142 | K14: ='Data Sheet'!K25/'Data Sheet'!K$17 -> 0.00039068555
B15: ='Data Sheet'!A26 -> Depreciation | C15: ='Data Sheet'!C26/'Data Sheet'!C$17 -> 4.6625077e-05 | D15: ='Data Sheet'!D26/'Data Sheet'!D$17 -> 3.8685233e-05 | E15: ='Data Sheet'!E26/'Data Sheet'!E$17 -> 3.7767855e-05 | F15: ='Data Sheet'!F26/'Data Sheet'!F$17 -> 3.7723681e-05 | G15: ='Data Sheet'!G26/'Data Sheet'!G$17 -> 3.4274593e-05 | H15: ='Data Sheet'!H26/'Data Sheet'!H$17 -> 0.00028090404 | I15: ='Data Sheet'!I26/'Data Sheet'!I$17 -> 0.00069115411 | J15: ='Data Sheet'!J26/'Data Sheet'!J$17 -> 0.00059269651 | K15: ='Data Sheet'!K26/'Data Sheet'!K$17 -> 0.00035428161
B16: ='Data Sheet'!A27 -> Interest | C16: ='Data Sheet'!C27/'Data Sheet'!C$17 -> 0.73518954 | D16: ='Data Sheet'!D27/'Data Sheet'!D$17 -> 0.76133975 | E16: ='Data Sheet'!E27/'Data Sheet'!E$17 -> 0.71625011 | F16: ='Data Sheet'!F27/'Data Sheet'!F$17 -> 0.73499204 | G16: ='Data Sheet'!G27/'Data Sheet'!G$17 -> 0.75722263 | H16: ='Data Sheet'!H27/'Data Sheet'!H$17 -> 0.71253561 | I16: ='Data Sheet'!I27/'Data Sheet'!I$17 -> 0.69336009 | J16: ='Data Sheet'!J27/'Data Sheet'!J$17 -> 0.73548368 | K16: ='Data Sheet'!K27/'Data Sheet'!K$17 -> 0.75440478
B17: ='Data Sheet'!A28 -> Profit before tax | C17: ='Data Sheet'!C28/'Data Sheet'!C$17 -> 0.2597563 | D17: ='Data Sheet'!D28/'Data Sheet'!D$17 -> 0.2357887 | E17: ='Data Sheet'!E28/'Data Sheet'!E$17 -> 0.27975082 | F17: ='Data Sheet'!F28/'Data Sheet'!F$17 -> 0.26061495 | G17: ='Data Sheet'!G28/'Data Sheet'!G$17 -> 0.23784258 | H17: ='Data Sheet'!H28/'Data Sheet'!H$17 -> 0.28002455 | I17: ='Data Sheet'!I28/'Data Sheet'!I$17 -> 0.30001655 | J17: ='Data Sheet'!J28/'Data Sheet'!J$17 -> 0.25997541 | K17: ='Data Sheet'!K28/'Data Sheet'!K$17 -> 0.24064541
... B20: ='Data Sheet'!A31 -> Dividend Amount | C20: ='Data Sheet'!C31/'Data Sheet'!C$17 -> 0.04522366 | D20: ='Data Sheet'!D31/'Data Sheet'!D$17 -> 0.041261669 | E20: ='Data Sheet'!E31/'Data Sheet'!E$17 -> 0.040494694 | F20: ='Data Sheet'!F31/'Data Sheet'!F$17 -> 0.035892286 | G20: ='Data Sheet'!G31/'Data Sheet'!G$17 -> 0 | H20: ='Data Sheet'!H31/'Data Sheet'!H$17 -> 0.087009868 | I20: ='Data Sheet'!I31/'Data Sheet'!I$17 -> 0.090130339 | J20: ='Data Sheet'!J31/'Data Sheet'!J$17 -> 0.082635215 | K20: ='Data Sheet'!K31/'Data Sheet'!K$17 -> 0.073568978
B22: ="Common-Size Balance Sheet"&" - "&'Data Sheet'!$B$1 -> Common-Size Balance Sheet - INDIAN RAILWAY FINANCE CORPORATION LTD
B24: Particulars | C24: =C4 -> 42460 | D24: =D4 -> 42825 | E24: =E4 -> 43190 | F24: =F4 -> 43555 | G24: =G4 -> 43921 | H24: =H4 -> 44286 | I24: =I4 -> 44651 | J24: =J4 -> 45016 | K24: =K4 -> 45382
B26: Total Liabilities | C26: ='Data Sheet'!C61/'Data Sheet'!C$61 -> 1 | D26: ='Data Sheet'!D61/'Data Sheet'!D$61 -> 1 | E26: ='Data Sheet'!E61/'Data Sheet'!E$61 -> 1 | F26: ='Data Sheet'!F61/'Data Sheet'!F$61 -> 1 | G26: ='Data Sheet'!G61/'Data Sheet'!G$61 -> 1 | H26: ='Data Sheet'!H61/'Data Sheet'!H$61 -> 1 | I26: ='Data Sheet'!I61/'Data Sheet'!I$61 -> 1 | J26: ='Data Sheet'!J61/'Data Sheet'!J$61 -> 1 | K26: ='Data Sheet'!K61/'Data Sheet'!K$61 -> 1
B27: ='Data Sheet'!A57 -> Equity Share Capital | C27: ='Data Sheet'!C57/'Data Sheet'!C$61 -> 0.041756861 | D27: ='Data Sheet'!D57/'Data Sheet'!D$61 -> 0.05033921 | E27: ='Data Sheet'!E57/'Data Sheet'!E$61 -> 0.040419446 | F27: ='Data Sheet'!F57/'Data Sheet'!F$61 -> 0.045403176 | G27: ='Data Sheet'!G57/'Data Sheet'!G$61 -> 0.04312262 | H27: ='Data Sheet'!H57/'Data Sheet'!H$61 -> 0.034347292 | I27: ='Data Sheet'!I57/'Data Sheet'!I$61 -> 0.02904241 | J27: ='Data Sheet'!J57/'Data Sheet'!J$61 -> 0.026650916 | K27: ='Data Sheet'!K57/'Data Sheet'!K$61 -> 0.026940803
B28: ='Data Sheet'!A58 -> Reserves | C28: ='Data Sheet'!C58/'Data Sheet'!C$61 -> 0.064565174 | D28: ='Data Sheet'!D58/'Data Sheet'!D$61 -> 0.042291983 | E28: ='Data Sheet'!E58/'Data Sheet'!E$61 -> 0.045843234 | F28: ='Data Sheet'!F58/'Data Sheet'!F$61 -> 0.075740158 | G28: ='Data Sheet'!G58/'Data Sheet'!G$61 -> 0.066856675 | H28: ='Data Sheet'!H58/'Data Sheet'!H$61 -> 0.060042023 | I28: ='Data Sheet'!I58/'Data Sheet'!I$61 -> 0.062064573 | J28: ='Data Sheet'!J58/'Data Sheet'!J$61 -> 0.064466434 | K28: ='Data Sheet'!K58/'Data Sheet'!K$61 -> 0.07444108
B29: ='Data Sheet'!A59 -> Borrowings | C29: ='Data Sheet'!C59/'Data Sheet'!C$61 -> 0.807222 | D29: ='Data Sheet'!D59/'Data Sheet'!D$61 -> 0.82063373 | E29: ='Data Sheet'!E59/'Data Sheet'!E$61 -> 0.8299184 | F29: ='Data Sheet'!F59/'Data Sheet'!F$61 -> 0.84186656 | G29: ='Data Sheet'!G59/'Data Sheet'!G$61 -> 0.85071944 | H29: ='Data Sheet'!H59/'Data Sheet'!H$61 -> 0.84930606 | I29: ='Data Sheet'!I59/'Data Sheet'!I$61 -> 0.86323788 | J29: ='Data Sheet'!J59/'Data Sheet'!J$61 -> 0.85434368 | K29: ='Data Sheet'!K59/'Data Sheet'!K$61 -> 0.84941959
B30: ='Data Sheet'!A60 -> Other Liabilities | C30: ='Data Sheet'!C60/'Data Sheet'!C$61 -> 0.086455962 | D30: ='Data Sheet'!D60/'Data Sheet'!D$61 -> 0.086735072 | E30: ='Data Sheet'!E60/'Data Sheet'!E$61 -> 0.083818919 | F30: ='Data Sheet'!F60/'Data Sheet'!F$61 -> 0.036990109 | G30: ='Data Sheet'!G60/'Data Sheet'!G$61 -> 0.039301262 | H30: ='Data Sheet'!H60/'Data Sheet'!H$61 -> 0.056304627 | I30: ='Data Sheet'!I60/'Data Sheet'!I$61 -> 0.04565514 | J30: ='Data Sheet'!J60/'Data Sheet'!J$61 -> 0.054538968 | K30: ='Data Sheet'!K60/'Data Sheet'!K$61 -> 0.049198525
B32: Total Assets | C32: ='Data Sheet'!C66/'Data Sheet'!C$66 -> 1 | D32: ='Data Sheet'!D66/'Data Sheet'!D$66 -> 1 | E32: ='Data Sheet'!E66/'Data Sheet'!E$66 -> 1 | F32: ='Data Sheet'!F66/'Data Sheet'!F$66 -> 1 | G32: ='Data Sheet'!G66/'Data Sheet'!G$66 -> 1 | H32: ='Data Sheet'!H66/'Data Sheet'!H$66 -> 1 | I32: ='Data Sheet'!I66/'Data Sheet'!I$66 -> 1 | J32: ='Data Sheet'!J66/'Data Sheet'!J$66 -> 1 | K32: ='Data Sheet'!K66/'Data Sheet'!K$66 -> 1
B33: ='Data Sheet'!A62 -> Net Block | C33: ='Data Sheet'!C62/'Data Sheet'!C$66 -> 0.00010848669 | D33: ='Data Sheet'!D62/'Data Sheet'!D$66 -> 8.8854862e-05 | E33: ='Data Sheet'!E62/'Data Sheet'!E$66 -> 6.9920836e-05 | F33: ='Data Sheet'!F62/'Data Sheet'!F$66 -> 5.4597304e-05 | G33: ='Data Sheet'!G62/'Data Sheet'!G$66 -> 4.0108292e-05 | H33: ='Data Sheet'!H62/'Data Sheet'!H$66 -> 0.00011921735 | I33: ='Data Sheet'!I62/'Data Sheet'!I$66 -> 8.4359264e-05 | J33: ='Data Sheet'!J62/'Data Sheet'!J$66 -> 3.9134613e-05 | K33: ='Data Sheet'!K62/'Data Sheet'!K$66 -> 4.5456192e-05
B34: ='Data Sheet'!A63 -> Capital Work in Progress | C34: ='Data Sheet'!C63/'Data Sheet'!C$66 -> 0 | D34: ='Data Sheet'!D63/'Data Sheet'!D$66 -> 0 | E34: ='Data Sheet'!E63/'Data Sheet'!E$66 -> 0 | F34: ='Data Sheet'!F63/'Data Sheet'!F$66 -> 0 | G34: ='Data Sheet'!G63/'Data Sheet'!G$66 -> 0 | H34: ='Data Sheet'!H63/'Data Sheet'!H$66 -> 0 | I34: ='Data Sheet'!I63/'Data Sheet'!I$66 -> 0 | J34: ='Data Sheet'!J63/'Data Sheet'!J$66 -> 0 | K34: ='Data Sheet'!K63/'Data Sheet'!K$66 -> 7.79249e-06
B35: ='Data Sheet'!A64 -> Investments | C35: ='Data Sheet'!C64/'Data Sheet'!C$66 -> 7.2601215e-05 | D35: ='Data Sheet'!D64/'Data Sheet'!D$66 -> 6.0702063e-05 | E35: ='Data Sheet'!E64/'Data Sheet'!E$66 -> 8.6580451e-05 | F35: ='Data Sheet'!F64/'Data Sheet'!F$66 -> 6.3648452e-05 | G35: ='Data Sheet'!G64/'Data Sheet'!G$66 -> 4.1777958e-05 | H35: ='Data Sheet'!H64/'Data Sheet'!H$66 -> 3.1486418e-05 | I35: ='Data Sheet'!I64/'Data Sheet'!I$66 -> 2.2223199e-05 | J35: ='Data Sheet'!J64/'Data Sheet'!J$66 -> 2.7857156e-05 | K35: ='Data Sheet'!K64/'Data Sheet'!K$66 -> 0.00011049668
B36: ='Data Sheet'!A65 -> Other Assets | C36: ='Data Sheet'!C74/'Data Sheet'!C$66 -> 0.98864543 | D36: ='Data Sheet'!D74/'Data Sheet'!D$66 -> 0.99979244 | E36: ='Data Sheet'!E74/'Data Sheet'!E$66 -> 0.9992253 | F36: ='Data Sheet'!F74/'Data Sheet'!F$66 -> 0.99948936 | G36: ='Data Sheet'!G74/'Data Sheet'!G$66 -> 0.99955238 | H36: ='Data Sheet'!H74/'Data Sheet'!H$66 -> 0.99864314 | I36: ='Data Sheet'!I74/'Data Sheet'!I$66 -> 0.55321627 | J36: ='Data Sheet'!J74/'Data Sheet'!J$66 -> 0.50254507 | K36: ='Data Sheet'!K74/'Data Sheet'!K$66 -> 0.46351922
B37: ='Data Sheet'!A67 -> Receivables | C37: ='Data Sheet'!C67/'Data Sheet'!C$66 -> 0 | D37: ='Data Sheet'!D67/'Data Sheet'!D$66 -> 0 | E37: ='Data Sheet'!E67/'Data Sheet'!E$66 -> 0 | F37: ='Data Sheet'!F67/'Data Sheet'!F$66 -> 0 | G37: ='Data Sheet'!G67/'Data Sheet'!G$66 -> 0 | H37: ='Data Sheet'!H67/'Data Sheet'!H$66 -> 0 | I37: ='Data Sheet'!I67/'Data Sheet'!I$66 -> 0.44600294 | J37: ='Data Sheet'!J67/'Data Sheet'!J$66 -> 0.49628332 | K37: ='Data Sheet'!K67/'Data Sheet'!K$66 -> 0.53535355
B38: ='Data Sheet'!A68 -> Inventory | C38: ='Data Sheet'!C68/'Data Sheet'!C$66 -> 0 | D38: ='Data Sheet'!D68/'Data Sheet'!D$66 -> 0 | E38: ='Data Sheet'!E68/'Data Sheet'!E$66 -> 0 | F38: ='Data Sheet'!F68/'Data Sheet'!F$66 -> 0 | G38: ='Data Sheet'!G68/'Data Sheet'!G$66 -> 0 | H38: ='Data Sheet'!H68/'Data Sheet'!H$66 -> 0 | I38: ='Data Sheet'!I68/'Data Sheet'!I$66 -> 0 | J38: ='Data Sheet'!J68/'Data Sheet'!J$66 -> 0 | K38: ='Data Sheet'!K68/'Data Sheet'!K$66 -> 0
B39: ='Data Sheet'!A69 -> Cash & Bank | C39: ='Data Sheet'!C69/'Data Sheet'!C$66 -> 0.011173484 | D39: ='Data Sheet'!D69/'Data Sheet'!D$66 -> 5.8002479e-05 | E39: ='Data Sheet'!E69/'Data Sheet'!E$66 -> 0.00061820176 | F39: ='Data Sheet'!F69/'Data Sheet'!F$66 -> 0.00039239392 | G39: ='Data Sheet'!G69/'Data Sheet'!G$66 -> 0.00036572954 | H39: ='Data Sheet'!H69/'Data Sheet'!H$66 -> 0.0012061558 | I39: ='Data Sheet'!I69/'Data Sheet'!I$66 -> 0.00067420741 | J39: ='Data Sheet'!J69/'Data Sheet'!J$66 -> 0.0011046198 | K39: ='Data Sheet'!K69/'Data Sheet'!K$66 -> 0.00096348573

Sheet Forecasting
B2: ='Data Sheet'!$B$1&" - "&'Data Sheet'!A17&" "&"Forecasting" -> INDIAN RAILWAY FINANCE CORPORATION LTD - Sales Forecasting | G2: ='Data Sheet'!$B$1&" - "&'Historical FS'!B22&" "&"Forecasting" -> INDIAN RAILWAY FINANCE CORPORATION LTD - EBITDA Forecasting | L2: ='Data Sheet'!$B$1&" - "&'Historical FS'!B37&" "&"Forecasting" -> INDIAN RAILWAY FINANCE CORPORATION LTD - Net Profit Forecasting
B3: Year weight | C3: Year | D3: Sales | E3: Sales Growth | G3: Year weight | H3: Year | I3: EBITDA | J3: EBITDA Growth | L3: Year weight | M3: Year | N3: Net profit | O3: Net profit Growth
B4: 1 | C4: =IFERROR('Data Sheet'!$B$16,0) -> 42094 | D4: {=TRANSPOSE('Historical FS'!C7:L7)} -> 6939.19 | G4: 1 | H4: =IFERROR('Data Sheet'!$B$16,0) -> 42094 | I4: {=TRANSPOSE('Historical FS'!C22:L22)} -> 6905.48 | L4: 1 | M4: =IFERROR('Data Sheet'!$B$16,0) -> 42094 | N4: {=TRANSPOSE('Historical FS'!C37:L37)} -> 758.3
B5: =B4+1 -> 2 | C5: =C4+365 -> 42459 | D5: 7506.69 | E5: =D5/D4-1 -> 0.081781879 | G5: =G4+1 -> 2 | H5: =H4+365 -> 42459 | I5: 7468.49 | J5: =I5/I4-1 -> 0.0815309 | L5: =L4+1 -> 2 | M5: =M4+365 -> 42459 | N5: 848.69 | O5: =N5/N4-1 -> 0.11920084
B6: =B5+1 -> 3 | C6: =C5+365 -> 42824 | D6: 9047.38 | E6: =D6/D5-1 -> 0.20524226 | G6: =G5+1 -> 3 | H6: =H5+365 -> 42824 | I6: 9021.49 | J6: =I6/I5-1 -> 0.20794029 | L6: =L5+1 -> 3 | M6: =M5+365 -> 42824 | N6: 933.81 | O6: =N6/N5-1 -> 0.10029575
B7: =B6+1 -> 4 | C7: =C6+365 -> 43189 | D7: 9267.14 | E7: =D7/D6-1 -> 0.024289905 | G7: =G6+1 -> 4 | H7: =H6+365 -> 43189 | I7: 9229.2 | J7: =I7/I6-1 -> 0.023023913 | L7: =L6+1 -> 4 | M7: =M6+365 -> 43189 | N7: 2054.66 | O7: =N7/N6-1 -> 1.2002977
B8: =B7+1 -> 5 | C8: =C7+365 -> 43554 | D8: 11133.59 | E8: =D8/D7-1 -> 0.20140518 | G8: =G7+1 -> 5 | H8: =H7+365 -> 43554 | I8: 11085.12 | J8: =I8/I7-1 -> 0.20109219 | L8: =L7+1 -> 5 | M8: =M7+365 -> 43554 | N8: 2254.74 | O8: =N8/N7-1 -> 0.097378642
B9: =B8+1 -> 6 | C9: =C8+365 -> 43919 | D9: 13421.02 | E9: =D9/D8-1 -> 0.20545305 | G9: =G8+1 -> 6 | H9: =H8+365 -> 43919 | I9: 13355.19 | J9: =I9/I8-1 -> 0.20478533 | L9: =L8+1 -> 6 | M9: =M8+365 -> 43919 | N9: 3192.09 | O9: =N9/N8-1 -> 0.41572421
B10: =B9+1 -> 7 | C10: =C9+365 -> 44284 | D10: 15770.51 | E10: =D10/D9-1 -> 0.17506046 | G10: =G9+1 -> 7 | H10: =H9+365 -> 44284 | I10: 15657.28 | J10: =I10/I9-1 -> 0.17237419 | L10: =L9+1 -> 7 | M10: =M9+365 -> 44284 | N10: 4416.13 | O10: =N10/N9-1 -> 0.38346037
B11: =B10+1 -> 8 | C11: =C10+365 -> 44649 | D11: 20299.38 | E11: =D11/D10-1 -> 0.28717334 | G11: =G10+1 -> 8 | H11: =H10+365 -> 44649 | I11: 20176.74 | J11: =I11/I10-1 -> 0.28864911 | L11: =L10+1 -> 8 | M11: =M10+365 -> 44649 | N11: 6089.83 | O11: =N11/N10-1 -> 0.378997
B12: =B11+1 -> 9 | C12: =C11+365 -> 45014 | D12: 23722.09 | E12: =D12/D11-1 -> 0.16861155 | G12: =G11+1 -> 9 | H12: =H11+365 -> 45014 | I12: 23587.77 | J12: =I12/I11-1 -> 0.16905754 | L12: =L11+1 -> 9 | M12: =M11+365 -> 45014 | N12: 6167.16 | O12: =N12/N11-1 -> 0.01269822
B13: =B12+1 -> 10 | C13: =C12+365 -> 45379 | D13: 26645.47 | E13: =D13/D12-1 -> 0.1232345 | G13: =G12+1 -> 10 | H13: =H12+365 -> 45379 | I13: 26512.61 | J13: =I13/I12-1 -> 0.12399816 | L13: =L12+1 -> 10 | M13: =M12+365 -> 45379 | N13: 6412.11 | O13: =N13/N12-1 -> 0.039718444
B14: =B13+1 -> 11 | C14: =C13+365 -> 45744 | D14: =FORECAST(B14,$D$4:$D$13,$B$4:$B$13) -> 26672.641 | E14: =D14/D13-1 -> 0.0010197356 | G14: =G13+1 -> 11 | H14: =H13+365 -> 45744 | I14: =FORECAST(G14,$I$4:$I$13,$G$4:$G$13) -> 26520.927 | J14: =I14/I13-1 -> 0.00031368721 | L14: =L13+1 -> 11 | M14: =M13+365 -> 45744 | N14: =FORECAST(L14,$N$4:$N$13,$L$4:$L$13) -> 7376.6 | O14: =N14/N13-1 -> 0.15041695
B15: =B14+1 -> 12 | C15: =C14+365 -> 46109 | D15: =FORECAST(B15,$D$4:$D$13,$B$4:$B$13) -> 28908.531 | E15: =D15/D14-1 -> 0.083827096 | G15: =G14+1 -> 12 | H15: =H14+365 -> 46109 | I15: =FORECAST(G15,$I$4:$I$13,$G$4:$G$13) -> 28742.925 | J15: =I15/I14-1 -> 0.083782824 | L15: =L14+1 -> 12 | M15: =M14+365 -> 46109 | N15: =FORECAST(L15,$N$4:$N$13,$L$4:$L$13) -> 8115.4815 | O15: =N15/N14-1 -> 0.10016559
B16: =B15+1 -> 13 | C16: =C15+365 -> 46474 | D16: =FORECAST(B16,$D$4:$D$13,$B$4:$B$13) -> 31144.421 | E16: =D16/D15-1 -> 0.077343606 | G16: =G15+1 -> 13 | H16: =H15+365 -> 46474 | I16: =FORECAST(G16,$I$4:$I$13,$G$4:$G$13) -> 30964.923 | J16: =I16/I15-1 -> 0.077305916 | L16: =L15+1 -> 13 | M16: =M15+365 -> 46474 | N16: =FORECAST(L16,$N$4:$N$13,$L$4:$L$13) -> 8854.3629 | O16: =N16/N15-1 -> 0.091045917
B17: =B16+1 -> 14 | C17: =C16+365 -> 46839 | D17: =FORECAST(B17,$D$4:$D$13,$B$4:$B$13) -> 33380.312 | E17: =D17/D16-1 -> 0.071791029 | G17: =G16+1 -> 14 | H17: =H16+365 -> 46839 | I17: =FORECAST(G17,$I$4:$I$13,$G$4:$G$13) -> 33186.921 | J17: =I17/I16-1 -> 0.071758555 | L17: =L16+1 -> 14 | M17: =M16+365 -> 46839 | N17: =FORECAST(L17,$N$4:$N$13,$L$4:$L$13) -> 9593.2444 | O17: =N17/N16-1 -> 0.083448291
B18: =B17+1 -> 15 | C18: =C17+365 -> 47204 | D18: =FORECAST(B18,$D$4:$D$13,$B$4:$B$13) -> 35616.202 | E18: =D18/D17-1 -> 0.066982301 | G18: =G17+1 -> 15 | H18: =H17+365 -> 47204 | I18: =FORECAST(G18,$I$4:$I$13,$G$4:$G$13) -> 35408.919 | J18: =I18/I17-1 -> 0.06695403 | L18: =L17+1 -> 15 | M18: =M17+365 -> 47204 | N18: =FORECAST(L18,$N$4:$N$13,$L$4:$L$13) -> 10332.126 | O18: =N18/N17-1 -> 0.077021019

Sheet Data>

Sheet Data Sheet
A1: COMPANY NAME | B1: INDIAN RAILWAY FINANCE CORPORATION LTD | E1: =IF(B2<>B3, "A NEW VERSION OF THE WORKSHEET IS AVAILABLE", "")
A2: LATEST VERSION | B2: 2.1 | E2: PLEASE DO NOT MAKE ANY CHANGES TO THIS SHEET
A3: CURRENT VERSION | B3: 2.1
A5: META
A6: Number of shares | B6: =IF(B9>0, B9/B8, 0) -> 1306.8506
A7: Face Value | B7: 10
A8: Current Price | B8: 156.81
A9: Market Capitalization | B9: 204927.24
A15: PROFIT & LOSS
A16: Report Date | B16: 42094 | C16: 42460 | D16: 42825 | E16: 43190 | F16: 43555 | G16: 43921 | H16: 44286 | I16: 44651 | J16: 45016 | K16: 45382
A17: Sales | B17: 6939.19 | C17: 7506.69 | D17: 9047.38 | E17: 9267.14 | F17: 11133.59 | G17: 13421.02 | H17: 15770.51 | I17: 20299.38 | J17: 23722.09 | K17: 26645.47
A18: Raw Material Cost
A19: Change in Inventory
A20: Power and Fuel | B20: 0.21 | C20: 0.2 | D20: 0.22 | E20: 0.24 | F20: 0.22 | G20: 0.26 | H20: 0.24 | I20: 0.21 | J20: 0.23 | K20: 0.25
A21: Other Mfr. Exp | G21: 2.08 | H21: 2.62 | I21: 3.95 | J21: 3.92 | K21: 3.97
A22: Employee Cost | B22: 3.1 | C22: 4.09 | D22: 3 | E22: 5.53 | F22: 6.47 | G22: 6.5 | H22: 8.01 | I22: 11.12 | J22: 13.25 | K22: 11.34
A23: Selling and admin | B23: 29.93 | C23: 33.13 | D23: 21.98 | E23: 6.94 | F23: 4.68 | G23: 4.08 | H23: 5.04 | I23: 6.87 | J23: 8.13 | K23: 7.19
A24: Other Expenses | B24: 0.47 | C24: 0.78 | D24: 0.69 | E24: 25.23 | F24: 37.1 | G24: 52.91 | H24: 97.32 | I24: 100.49 | J24: 108.79 | K24: 110.11
A25: Other Income | B25: 0.97 | C25: 0.61 | D25: 0.26 | E25: 1.23 | F25: -0.02 | G25: 0.06 | H25: 0.33 | I25: 2.22 | J25: 40.66 | K25: 10.41
A26: Depreciation | B26: 0.44 | C26: 0.35 | D26: 0.35 | E26: 0.35 | F26: 0.42 | G26: 0.46 | H26: 4.43 | I26: 14.03 | J26: 14.06 | K26: 9.44
A27: Interest | B27: 4991.83 | C27: 5518.84 | D27: 6888.13 | E27: 6637.59 | F27: 8183.1 | G27: 10162.7 | H27: 11237.05 | I27: 14074.78 | J27: 17447.21 | K27: 20101.47
A28: Profit before tax | B28: 1914.18 | C28: 1949.91 | D28: 2133.27 | E28: 2592.49 | F28: 2901.58 | G28: 3192.09 | H28: 4416.13 | I28: 6090.15 | J28: 6167.16 | K28: 6412.11
A29: Tax | B29: 1155.88 | C29: 1101.22 | D29: 1199.46 | E29: 537.83 | F29: 646.84 | I29: 0.32
A30: Net profit | B30: 758.3 | C30: 848.69 | D30: 933.81 | E30: 2054.66 | F30: 2254.75 | G30: 3192.1 | H30: 4416.13 | I30: 6089.84 | J30: 6167.16 | K30: 6412.1
A31: Dividend Amount | B31: 151.96 | C31: 339.48 | D31: 373.31 | E31: 375.27 | F31: 399.61 | H31: 1372.19 | I31: 1829.59 | J31: 1960.28 | K31: 1960.28
A40: Quarters
A41: Report Date | B41: 44651 | C41: 44742 | D41: 44834 | E41: 44926 | F41: 45016 | G41: 45107 | H41: 45199 | I41: 45291 | J41: 45382 | K41: 45473
A42: Sales | B42: 5931.72 | C42: 5627.44 | D42: 5809.8 | E42: 6218.1 | F42: 6194.02 | G42: 6679.17 | H42: 6766.63 | I42: 6736.6 | J42: 6473.56 | K42: 6765.63
A43: Expenses | B43: 82.44 | C43: 22.74 | D43: 34.06 | E43: 30.51 | F43: 47.01 | G43: 29.26 | H43: 33.97 | I43: 35.47 | J43: 34.22 | K43: 32.69
A44: Other Income | B44: 1.08 | C44: 0.03 | D44: 0.59 | E44: 3.92 | F44: 36.25 | G44: 1.86 | H44: 0.85 | I44: 3.42 | J44: 4.43 | K44: 0.39
A45: Depreciation | B45: 4.72 | C45: 3.51 | D45: 3.51 | E45: 3.73 | F45: 3.32 | G45: 4.23 | H45: 2.15 | I45: 1.33 | J45: 1.73 | K45: 1.59
A46: Interest | B46: 4352.83 | C46: 3939.64 | D46: 4058.54 | E46: 4554.33 | F46: 4894.7 | G46: 5090.97 | H46: 5181.49 | I46: 5104.29 | J46: 4724.72 | K46: 5154.91
A47: Profit before tax | B47: 1492.81 | C47: 1661.58 | D47: 1714.28 | E47: 1633.45 | F47: 1285.24 | G47: 1556.57 | H47: 1549.87 | I47: 1598.93 | J47: 1717.32 | K47: 1576.83
A48: Tax | B48: 0.32
A49: Net profit | B49: 1492.5 | C49: 1661.58 | D49: 1714.28 | E49: 1633.45 | F49: 1285.24 | G49: 1556.57 | H49: 1549.87 | I49: 1598.93 | J49: 1717.32 | K49: 1576.83
A50: Operating Profit | B50: 5849.28 | C50: 5604.7 | D50: 5775.74 | E50: 6187.59 | F50: 6147.01 | G50: 6649.91 | H50: 6732.66 | I50: 6701.13 | J50: 6439.34 | K50: 6732.94
A55: BALANCE SHEET
A56: Report Date | B56: 42094 | C56: 42460 | D56: 42825 | E56: 43190 | F56: 43555 | G56: 43921 | H56: 44286 | I56: 44651 | J56: 45016 | K56: 45382
A57: Equity Share Capital | B57: 3583.96 | C57: 4526.46 | D57: 6526.46 | E57: 6526.46 | F57: 9380.46 | G57: 11880.46 | H57: 13068.51 | I57: 13068.51 | J57: 13068.51 | K57: 13068.51
